<?xml version="1.0" ?>
<!-- =================================================================================== -->
<!-- |    This document was autogenerated by xacro from /home/nvidia/catkin_workspace/src/jaka_robot/jaka_description/urdf/jaka_a5.urdf.xacro | -->
<!-- |    EDITING THIS FILE BY HAND IS NOT RECOMMENDED                                 | -->
<!-- =================================================================================== -->
<robot name="jaka_a5">
    <!--fixed world-->
    <link name="world" />
    <joint name="fixed" type="fixed">
        <parent link="world" />
        <child link="link_0" />
    </joint>
    <!--sub-link defining detailed meshes for collision with environment-->
    <link name="link_0">
        <inertial>
            <origin rpy="0 0 0" xyz="0.0028167 -0.00019454 0.019544" />
            <mass value="0.52663" />
            <inertia ixx="0.0006297" ixy="6.7091e-08" ixz="3.4682e-06" iyy="0.00095727" iyz="2.4476e-07" izz="0.0014514" />
        </inertial>
        <visual>
            <origin rpy="0 0 0" xyz="0 0 0" />
            <geometry>
                <mesh filename="package://jaka_description/meshes/jaka_a5_meshes/Link_0.STL" />
            </geometry>
        </visual>
        <collision>
            <origin rpy="0 0 0" xyz="0 0 0" />
            <geometry>
                <mesh filename="package://jaka_description/meshes/jaka_a5_meshes/Link_0.STL" />
            </geometry>
            <material name="">
                <color rgba="0.86667 0.86667 0.8902 1" />
            </material>
        </collision>
    </link>
    <!--sub-link defining detailed meshes for collision with environment-->
    <link name="link_1">
        <inertial>
            <origin rpy="0 0 0" xyz="-2.5186E-07 0.0033226 -0.001509" />
            <mass value="15.135" />
            <inertia ixx="0.044302" ixy="1.5349e-07" ixz="-6.1966e-07" iyy="0.043091" iyz="1.4326e-05" izz="0.030523" />
        </inertial>
        <visual>
            <origin rpy="0 0 0" xyz="0 0 0" />
            <geometry>
                <mesh filename="package://jaka_description/meshes/jaka_a5_meshes/Link_1.STL" />
            </geometry>
        </visual>
        <collision>
            <origin rpy="0 0 0" xyz="0 0 0" />
            <geometry>
                <mesh filename="package://jaka_description/meshes/jaka_a5_meshes/Link_1.STL" />
            </geometry>
            <material name="">
                <color rgba="0.79216 0.81961 0.93333 1" />
            </material>
        </collision>
    </link>
    <joint name="joint_1" type="revolute">
        <origin rpy="0 0 0" xyz="0 -0.00022535 0.12015" />
        <parent link="link_0" />
        <child link="link_1" />
        <axis xyz="0 0 1" />
        <limit effort="2000" lower="-6.28" upper="6.28" velocity="3.665" />
    </joint>
    <!--sub-link defining detailed meshes for collision with environment-->
    <link name="link_2">
        <inertial>
            <origin rpy="0 0 0" xyz="0.215 4.9016E-09 -0.14314" />
            <mass value="5.7891" />
            <inertia ixx="0.013095" ixy="-4.1856e-09" ixz="2.9241e-08" iyy="0.20279" iyz="2.1723e-09" izz="0.19928" />
        </inertial>
        <visual>
            <origin rpy="0 0 0" xyz="0 0 0" />
            <geometry>
                <mesh filename="package://jaka_description/meshes/jaka_a5_meshes/Link_2.STL" />
            </geometry>
        </visual>
        <collision>
            <origin rpy="0 0 0" xyz="0 0 0" />
            <geometry>
                <mesh filename="package://jaka_description/meshes/jaka_a5_meshes/Link_2.STL" />
            </geometry>
            <material name="">
                <color rgba="0.79216 0.81961 0.93333 1" />
            </material>
        </collision>
    </link>
    <joint name="joint_2" type="revolute">
        <origin rpy="1.5708 0 0" xyz="0 0 0" />
        <parent link="link_1" />
        <child link="link_2" />
        <axis xyz="0 0 1" />
        <limit effort="5000" lower="-1.48" upper="4.628" velocity="3.665" />
    </joint>
    <!--sub-link defining detailed meshes for collision with environment-->
    <link name="link_3">
        <inertial>
            <origin rpy="0 0 0" xyz="0.17601 -7.8489E-07 -0.0097984" />
            <mass value="2.5808" />
            <inertia ixx="0.0032112" ixy="1.1156e-07" ixz="-0.0022739" iyy="0.05921" iyz="3.3121e-08" izz="0.058511" />
        </inertial>
        <visual>
            <origin rpy="0 0 0" xyz="0 0 0" />
            <geometry>
                <mesh filename="package://jaka_description/meshes/jaka_a5_meshes/Link_3.STL" />
            </geometry>
        </visual>
        <collision>
            <origin rpy="0 0 0" xyz="0 0 0" />
            <geometry>
                <mesh filename="package://jaka_description/meshes/jaka_a5_meshes/Link_3.STL" />
            </geometry>
            <material name="">
                <color rgba="0.79216 0.81961 0.93333 1" />
            </material>
        </collision>
    </link>
    <joint name="joint_3" type="revolute">
        <origin rpy="0 0 0" xyz="0.43 0 0" />
        <parent link="link_2" />
        <child link="link_3" />
        <axis xyz="0 0 1" />
        <limit effort="5000" lower="-3.05" upper="3.05" velocity="3.665" />
    </joint>
    <!--sub-link defining detailed meshes for collision with environment-->
    <link name="link_4">
        <inertial>
            <origin rpy="0 0 0" xyz="-2.1463E-06 -0.0059512 0.0026789" />
            <mass value="5.5377" />
            <inertia ixx="0.0092004" ixy="1.17e-07" ixz="-1.3683e-08" iyy="0.0052083" iyz="-8.5741e-05" izz="0.0089125" />
        </inertial>
        <visual>
            <origin rpy="0 0 0" xyz="0 0 0" />
            <geometry>
                <mesh filename="package://jaka_description/meshes/jaka_a5_meshes/Link_4.STL" />
            </geometry>
        </visual>
        <collision>
            <origin rpy="0 0 0" xyz="0 0 0" />
            <geometry>
                <mesh filename="package://jaka_description/meshes/jaka_a5_meshes/Link_4.STL" />
            </geometry>
            <material name="">
                <color rgba="0.84706 0.84706 0.84706 1" />
            </material>
        </collision>
    </link>
    <joint name="joint_4" type="revolute">
        <origin rpy="0 0 0" xyz="0.3685 0 -0.115" />
        <parent link="link_3" />
        <child link="link_4" />
        <axis xyz="0 0 1" />
        <limit effort="2000" lower="-1.48" upper="4.62" velocity="3.665" />
    </joint>
    <!--sub-link defining detailed meshes for collision with environment-->
    <link name="link_5">
        <inertial>
            <origin rpy="0 0 0" xyz="-2.2875E-08 -0.0015344 -0.0023275" />
            <mass value="0.81207" />
            <inertia ixx="0.0016825" ixy="2.829e-09" ixz="-1.1984e-08" iyy="0.00074766" iyz="3.2415e-06" izz="0.0016452" />
        </inertial>
        <visual>
            <origin rpy="0 0 0" xyz="0 0 0" />
            <geometry>
                <mesh filename="package://jaka_description/meshes/jaka_a5_meshes/Link_5.STL" />
            </geometry>
        </visual>
        <collision>
            <origin rpy="0 0 0" xyz="0 0 0" />
            <geometry>
                <mesh filename="package://jaka_description/meshes/jaka_a5_meshes/Link_5.STL" />
            </geometry>
            <material name="">
                <color rgba="0.79216 0.81961 0.93333 1" />
            </material>
        </collision>
    </link>
    <joint name="joint_5" type="revolute">
        <origin rpy="1.5708 -0.00010901 0" xyz="0 -0.1135 0" />
        <parent link="link_4" />
        <child link="link_5" />
        <axis xyz="0 0 1" />
        <limit effort="3000" lower="-6.28" upper="6.28" velocity="3.665" />
    </joint>
    <!--sub-link defining detailed meshes for collision with environment-->
    <link name="link_6">
        <inertial>
            <origin rpy="0 0 0" xyz="3.1532E-05 -1.4302E-05 -0.02023" />
            <mass value="1.336" />
            <inertia ixx="0.00066124" ixy="-6.979e-07" ixz="-6.4232e-07" iyy="0.00066646" iyz="8.1119e-07" izz="0.0010673" />
        </inertial>
        <visual>
            <origin rpy="0 0 0" xyz="0 0 0" />
            <geometry>
                <mesh filename="package://jaka_description/meshes/jaka_a5_meshes/Link_6.STL" />
            </geometry>
        </visual>
        <collision>
            <origin rpy="0 0 0" xyz="0 0 0" />
            <geometry>
                <mesh filename="package://jaka_description/meshes/jaka_a5_meshes/Link_6.STL" />
            </geometry>
            <material name="">
                <color rgba="0.84706 0.84706 0.84706 1" />
            </material>
        </collision>
    </link>
    <joint name="joint_6" type="revolute">
        <origin rpy="-1.5708 0 -0.00010901" xyz="0 0.107 0" />
        <parent link="link_5" />
        <child link="link_6" />
        <axis xyz="0 0 1" />
        <limit effort="1000" lower="-6.28" upper="6.28" velocity="3.665" />
    </joint>
    <transmission name="trans_joint_1">
        <type>transmission_interface/SimpleTransmission</type>
        <joint name="joint_1">
            <hardwareInterface>hardware_interface/EffortJointInterface</hardwareInterface>
        </joint>
        <actuator name="joint_1_motor">
            <hardwareInterface>hardware_interface/EffortJointInterface</hardwareInterface>
            <mechanicalReduction>1</mechanicalReduction>
        </actuator>
    </transmission>
    <transmission name="trans_joint_2">
        <type>transmission_interface/SimpleTransmission</type>
        <joint name="joint_2">
            <hardwareInterface>hardware_interface/EffortJointInterface</hardwareInterface>
        </joint>
        <actuator name="joint_2_motor">
            <hardwareInterface>hardware_interface/EffortJointInterface</hardwareInterface>
            <mechanicalReduction>1</mechanicalReduction>
        </actuator>
    </transmission>
    <transmission name="trans_joint_3">
        <type>transmission_interface/SimpleTransmission</type>
        <joint name="joint_3">
            <hardwareInterface>hardware_interface/EffortJointInterface</hardwareInterface>
        </joint>
        <actuator name="joint_3_motor">
            <hardwareInterface>hardware_interface/EffortJointInterface</hardwareInterface>
            <mechanicalReduction>1</mechanicalReduction>
        </actuator>
    </transmission>
    <transmission name="trans_joint_4">
        <type>transmission_interface/SimpleTransmission</type>
        <joint name="joint_4">
            <hardwareInterface>hardware_interface/EffortJointInterface</hardwareInterface>
        </joint>
        <actuator name="joint_4_motor">
            <hardwareInterface>hardware_interface/EffortJointInterface</hardwareInterface>
            <mechanicalReduction>1</mechanicalReduction>
        </actuator>
    </transmission>
    <transmission name="trans_joint_5">
        <type>transmission_interface/SimpleTransmission</type>
        <joint name="joint_5">
            <hardwareInterface>hardware_interface/EffortJointInterface</hardwareInterface>
        </joint>
        <actuator name="joint_5_motor">
            <hardwareInterface>hardware_interface/EffortJointInterface</hardwareInterface>
            <mechanicalReduction>1</mechanicalReduction>
        </actuator>
    </transmission>
    <transmission name="trans_joint_6">
        <type>transmission_interface/SimpleTransmission</type>
        <joint name="joint_6">
            <hardwareInterface>hardware_interface/EffortJointInterface</hardwareInterface>
        </joint>
        <actuator name="joint_6_motor">
            <hardwareInterface>hardware_interface/EffortJointInterface</hardwareInterface>
            <mechanicalReduction>1</mechanicalReduction>
        </actuator>
    </transmission>
    <gazebo>
        <plugin name="gazebo_ros_control" filename="libgazebo_ros_control.so">
            <robotNamespace>/</robotNamespace>
        </plugin>
    </gazebo>
</robot>

